Workbook

Sheet Summary
A1: Sector | B1: Subsector | C1: Year | D1: Total Emissions (MMTCO2e) | E1: CO2 Emissions (MMTCO2e) | F1: CH4 Emissions (MMTCO2e) | G1: N2O Emissions (MMTCO2e) | H1: VMT (billion miles) | I1: Total emissions factors in eGrid (Ib/MWh)
A2: Mobile Combustion | B2: Automobile | C2: 2021 | D2: 1.0288993 | E2: 1.0224834 | F2: 0.000561318 | G2: 0.005854545 | H2: 2.81
A3: Mobile Combustion | B3: Motorcycle | C3: 2021 | D3: 0.036643172 | E3: 0.036643172 | F3: 0 | G3: 0 | H3: 0.21
A4: Mobile Combustion | B4: Trucks | C4: 2021 | D4: 1.7896126 | E4: 1.7883623 | F4: 9.68e-05 | G4: 0.001153555 | H4: 3.87
A5: Mobile Combustion | B5: Buses | C5: 2021 | D5: 0.020234238 | E5: 0.020192843 | F5: 3.2e-06 | G5: 3.82e-05 | H5: 0.03
A6: Electricity Consumption | B6: Residential Electricity | C6: 2021 | D6: 0.61204779 | E6: 0.60700377 | F6: 0.002025709 | G6: 0.003018307 | I6: 543.852
A7: Electricity Consumption | B7: Commercial&Industrial Electricity | C7: 2021 | D7: 0.7028926 | E7: 0.69709991 | F7: 0.00232638 | G7: 0.003466307
A8: Solid Waste Landfills | B8: Landfill fuel combustion | C8: 2021 | D8: 0
A9: Solid Waste Landfills | B9: Landfill methane | C9: 2021 | D9: 0
A10: Stationary Combustion | B10: Residential fuel oil | C10: 2020 | D10: 0.76
A11: Stationary Combustion | B11: Residential natural gas | C11: 2020 | D11: 0.54
A12: Stationary Combustion | B12: Residential propane | C12: 2020 | D12: 0.06
A13: Stationary Combustion | B13: Commercial fuel | C13: 2020 | D13: 0.96
A14: Stationary Combustion | B14: Industrial fuel | C14: 2020 | D14: 0.339402
A15: Agriculture & Land management | B15: Organic fertilizer | C15: 2017 | D15: 9.88e-05
A16: Agriculture & Land management | B16: Synthetic fertilizer | C16: 2017 | D16: 0.029055486
A17: Agriculture & Land management | B17: Manure fertilizer | C17: 2017 | D17: 8.68e-05
A18: Wastewater treatment | B18: Wastewater | C18: 2021 | D18: 0.092857143
A19: Forestry | B19: Deciduous forest | C19: 2015 | D19: -0.54712577
... A21: Forestry | B21: Forested wetland | C21: 2015 | D21: -0.037731317
D22: =SUM(D2:D21) -> 6.3439387
E33: `

Sheet Recalculation
A1: Strategy | B1: Scenario | C1: Uncertainty | D1: Change in uncertainty | E1: GHG Reduction (MMTCO2e) | F1: Reduction for each scenario | G1: Reduction for each strategies
A2: M1 | B2: S1 | C2: U1 | D2: -0.1 | E2: =D2*Summary!D5 -> -0.0020234238 | F2: =SUM(E2:E4) -> -0.0060702714 | G2: =F2 -> -0.0060702714
C3: U4 | D3: -0.3 | E3: =D3*Summary!D5 -> -0.0060702714
C4: U8 | D4: 0.1 | E4: =D4*Summary!D5 -> 0.0020234238
A5: M2 | B5: S1 | C5: U1 | D5: -0.1 | E5: =D5*Summary!D5 -> -0.0020234238 | F5: =SUM(E5:E7) -> -0.0060702714 | G5: =SUM(F5,F8) -> -0.56572581
C6: U4 | D6: -0.3 | E6: =D6*Summary!D5 -> -0.0060702714
C7: U8 | D7: 0.1 | E7: =D7*Summary!D5 -> 0.0020234238
B8: S2 | C8: U1 | D8: 0.2 | E8: =D8*Summary!D5 -> 0.0040468476 | F8: =SUM(E8:E10) -> -0.55965553
C9: U2 | D9: -0.2 | E9: =D9*Summary!D2 -> -0.20577986
C10: U3 | D10: -0.2 | E10: =D10*Summary!D4 -> -0.35792252
B11: S4 | C11: U1 | D11: -0.1 | E11: =D11*Summary!D5 -> -0.0020234238 | F11: =SUM(E11:E13) -> -0.46283588
C12: U2 | D12: -0.1 | E12: =D12*Summary!D2 -> -0.10288993
C13: U3 | D13: -0.2 | E13: =D13*Summary!D4 -> -0.35792252
A14: M3 | B14: S3 | C14: U2 | D14: -0.2 | E14: =D14*Summary!D2 -> -0.20577986 | F14: =SUM(E14:E18) -> -1.2034761 | G14: =F14 -> -1.2034761
C15: U3 | D15: -0.2 | E15: =D15*Summary!D4 -> -0.35792252
C16: U5 | D16: -0.3 | E16: =D16*Summary!D2 -> -0.30866979
C17: U6 | D17: -0.3 | E17: =D17*Summary!D4 -> -0.53688378
C18: U8 | D18: 0.2 | E18: =D18*Summary!D2 -> 0.20577986
A19: E1 | B19: S5 | C19: U7 | D19: -0.2 | E19: =D19*(Summary!D6+Summary!D7) -> -0.26298808 | F19: =SUM(E19:E21) -> -0.72775945 | G19: =F19 -> -0.72775945
C20: U8 | D20: -0.3 | E20: =D20*(Summary!D6+Summary!D7) -> -0.39448212
C21: U9 | D21: -0.1 | E21: =D21*Summary!D7 -> -0.07028926
A22: E2 | B22: S5 | C22: U7 | D22: -0.2 | E22: =D22*(Summary!D6+Summary!D7) -> -0.26298808 | F22: =SUM(E22:E24) -> -0.72775945 | G22: =SUM(F22,F25,F26) -> -1.3852296
C23: U8 | D23: -0.3 | E23: =D23*(Summary!D6+Summary!D7) -> -0.39448212
C24: U9 | D24: -0.1 | E24: =D24*Summary!D7 -> -0.07028926
B25: S6 | C25: U8 | D25: -0.3 | E25: =D25*(Summary!D6+Summary!D7) -> -0.39448212 | F25: =E25 -> -0.39448212
B26: S7 | C26: U8 | D26: -0.2 | E26: =D26*(Summary!D6+Summary!D7) -> -0.26298808 | F26: =E26 -> -0.26298808
A27: E3 | B27: S6 | C27: U8 | D27: -0.3 | E27: =D27*(Summary!D6+Summary!D7) -> -0.39448212 | F27: =E27 -> -0.39448212 | G27: =SUM(F27:F28) -> -0.78896423
B28: S7 | C28: U8 | D28: -0.3 | E28: =D28*(Summary!D6+Summary!D7) -> -0.39448212 | F28: =E28 -> -0.39448212
A29: S1 | B29: S8 | C29: U10 | D29: -0.1 | E29: =D29*SUM(Summary!D10:D12) -> -0.136 | F29: =SUM(E29:E31) -> -1.1258206 | G29: =SUM(F29,F32) -> -2.2516412
C30: U11 | D30: -0.2 | E30: =D30*Summary!D13 -> -0.192
C31: U12 | D31: -0.3 | E31: =D31*SUM(Summary!D10:D14) -> -0.7978206
B32: S9 | C32: U10 | D32: -0.1 | E32: =D32*SUM(Summary!D10:D12) -> -0.136 | F32: =SUM(E32:E34) -> -1.1258206
C33: U11 | D33: -0.2 | E33: =D33*Summary!D13 -> -0.192
C34: U12 | D34: -0.3 | E34: =D34*SUM(Summary!D10:D14) -> -0.7978206
A35: S2 | B35: S9 | C35: U10 | D35: -0.1 | E35: =D35*SUM(Summary!D10:D12) -> -0.136 | F35: =SUM(E35:E37) -> -1.1258206 | G35: =F35 -> -1.1258206
C36: U11 | D36: -0.2 | E36: =D36*Summary!D13 -> -0.192
C37: U12 | D37: -0.3 | E37: =D37*SUM(Summary!D10:D14) -> -0.7978206
A38: W1 | B38: S10 | C38: U13 | D38: -0.2 | E38: =D38*Summary!D18 -> -0.018571429 | F38: =E38 -> -0.018571429 | G38: =F38 -> -0.018571429
A39: A1 | B39: S11 | C39: U14 | D39: -0.1 | E39: =D39*SUM(Summary!D15:D17) -> -0.0029241086 | F39: =E39 -> -0.0029241086 | G39: =SUM(F39:F40) -> -0.0087723258
B40: S12 | C40: U14 | D40: -0.2 | E40: =D40*SUM(Summary!D15:D17) -> -0.0058482172 | F40: =E40 -> -0.0058482172
...

Sheet Calculation
A1: Scenario | B1: Assumptions | C1: T.1 | D1: T.2 | E1: T.3 | F1: T.4 | G1: T.5 | H1: T.6 | I1: T.7 | J1: T.8 | K1: T.9 | L1: T.10 | M1: T.11 | N1: T.12 | O1: T.13 | P1: E.1 | Q1: E.2 | R1: E.3 | S1: E.4 | T1: E.5 | U1: E.6 | V1: E.7 | W1: E.8 | X1: E.9 | Y1: E.10 | Z1: E.11 | AA1: B.1 | AB1: B.2 | AC1: B.3 | AD1: B.4 | AE1: B.5 | AF1: B.6 | AG1: B.7 | AH1: B.8 | AI1: B.9 | AJ1: B.10 | AK1: B.11 | AL1: B.12 | AM1: B.13 | AN1: I.1 | AO1: I.2 | AP1: I.3 | AQ1: L.1 | AR1: L.2 | AS1: L.3 | AT1: L.4 | AU1: W.1 | AV1: W.2 | AW1: W.3 | AX1: W.4 | AY1: W.5 | AZ1: GHG Reduction (MMTCO2e) | BA1: GHG Reduction (TMTCO2e) | BB1: Percentage of reduction % | BC1: Activity 1 | BD1: % of reduction | BE1: Activity 2 | BF1: % of reduction | BG1: Activity 3 | BH1: % of increase | BI1: Activity 4 | BJ1: % of increase | BK1: Calculation Method
A2: T.a | B2: 10% of total buses in New Haven are school buses, all the school buses are switched to EVs | C2: X | AZ2: =0.1*Summary!D5-1000000000*0.1*Calculation!L5/(3000*2204.62*1000000) -> 0.0020234238 | BA2: =AZ2*1000 -> 2.0234238 | BB2: =AZ2/Summary!D$22*100 -> 0.031895387 | BC2: VMT (buses) | BD2: 10 | BG2: VMT (buses) | BH2: 10 in electricity generation emissions | BK2: 0.1*TEmi_buses-1000000000*0.1*VMT_buses/(3000*2204.62*1000000)
A3: T.b | B3: 5% trucks are in municipal fleet and adopting the hydrogen as the fuel sources; all hydrogen powered car are fuel cell electric cars, zero tailpipe emissions | D3: X | AZ3: =0.05*Summary!D4 -> 0.08948063 | BA3: =AZ3*1000 -> 89.48063 | BB3: =AZ3/Summary!D$22*100 -> 1.4104901 | BC3: VMT ( truck) | BD3: 5 | BK3: 0.05*Temi_trucks
A4: T.c | B4: Idling reduces the MPG by 10 percent for any types of vehicles (most influence the carbon dioxide emissions) ; 5% percent of the passenger cars, and 5% of the trucks and all buses are from municipal fleet | E4: X | AZ4: =(0.05*(Summary!E2+Summary!E4)+Summary!E5)*0.1 -> 0.016073513 | BA4: =AZ4*1000 -> 16.073513 | BB4: =AZ4/Summary!D$22*100 -> 0.25336804 | BC4: MPG(automobiles, trucks) | BD4: 0.5 | BE4: MPG(buses) | BF4: 10 | BK4: (0.05*(CEmi_automobile+CEmi_trucks)+CEmi_buses)*0.1
A5: T.d | B5: 10% increase in bus mileage and 5% decrease in passenger car mileage | F5: X | G5: X | H5: X | I5: X | J5: X | AZ5: =0.05*Summary!D2-0.1*Summary!D5 -> 0.049421541 | BA5: =AZ5*1000 -> 49.421541 | BB5: =AZ5/Summary!D$22*100 -> 0.77903561 | BC5: VMT (automobile) | BD5: 5 | BG5: VMT (buses) | BH5: 10 | BK5: 0.05*TEmi_automobile-0.1*TEmi_buses
A6: T.e | B6: 5% increase in bus mileage and 10% decrease in passenger car mileage | F6: X | G6: X | H6: X | I6: X | J6: X | AZ6: =0.1*Summary!D2-0.05*Summary!D5 -> 0.10187822 | BA6: =AZ6*1000 -> 101.87822 | BB6: =AZ6/Summary!D$22*100 -> 1.6059143 | BC6: VMT (automobile) | BD6: 10 | BG6: VMT (buses) | BH6: 5 | BK6: 0.1*TEmi_automobile-0.05*TEmi_buses
A7: T.f | B7: 5% increase in bus mileage and 5% decrease in passenger car mileage | F7: X | G7: X | H7: X | I7: X | J7: X | AZ7: =0.05*Summary!D2-0.05*Summary!D5 -> 0.050433253 | BA7: =AZ7*1000 -> 50.433253 | BB7: =AZ7/Summary!D$22*100 -> 0.7949833 | BC7: VMT (automobile) | BD7: 5 | BG7: VMT (buses) | BH7: 5 | BK7: 0.05*(TEmi_automobile-TEmi_buses)
A8: T.g | B8: 10% increase in bus mileage and 10% decrease in passenger car mileage | F8: X | G8: X | H8: X | I8: X | J8: X | AZ8: =0.1*Summary!D2-0.1*Summary!D5 -> 0.10086651 | BA8: =AZ8*1000 -> 100.86651 | BB8: =AZ8/Summary!D$22*100 -> 1.5899666 | BC8: VMT (automobile) | BD8: 10 | BG8: VMT (buses) | BH8: 10 | BK8: 0.1*(TEmi_automobile-TEmi_buses)
A9: T.h | B9: 20% increase in bus mileage and 10% decrease in passenger car mileage | F9: X | G9: X | H9: X | I9: X | J9: X | AZ9: =0.1*Summary!D2-0.2*Summary!D5 -> 0.098843083 | BA9: =AZ9*1000 -> 98.843083 | BB9: =AZ9/Summary!D$22*100 -> 1.5580712 | BC9: VMT (automobile) | BD9: 10 | BG9: VMT (buses) | BH9: 20 | BK9: 0.1*TEmi_automobile-0.2*TEmi_buses
A10: T.i | B10: 20% passenger cars are replaced by electric vehicles | K10: X | L10: X | M10: X | N10: X | AZ10: =0.2*Summary!D2-1000000000*(0.2*Summary!H2)/(3000*2204.62*1000000) -> 0.20569489 | BA10: =AZ10*1000 -> 205.69489 | BB10: =AZ10/Summary!D$22*100 -> 3.2423845 | BC10: VMT (automobile) | BD10: 20 | BG10: VMT (automobile) | BH10: 20 in electricity generation emissions | BK10: 0.2*TEmi_automobile-1000000000*(0.2*VMT_automobile)/(3000*2204.62*1000000)
A11: T.j | B11: 40% trucks are replaced by electric vehicles | K11: X | L11: X | M11: X | N11: X | AZ11: =0.4*Summary!D4-1000000000*(0.4*Summary!H4)/(3000*2204.62*1000000) -> 0.71561099 | BA11: =AZ11*1000 -> 715.61099 | BB11: =AZ11/Summary!D$22*100 -> 11.280232 | BC11: VMT (trucks) | BD11: 40 | BG11: VMT (trucks) | BH11: 40 in electricity generation emissions | BK11: 0.4*TEmi_truck-1000000000*(0.4*VMT_truck)/(3000*2204.62*1000000)
A12: T.k | B12: 5% reduction in the total vehicle emissions due to remote working schedule | M12: X | AZ12: =0.05*SUM(Summary!D2:D5) -> 0.14376947 | BA12: =AZ12*1000 -> 143.76947 | BB12: =AZ12/Summary!D$22*100 -> 2.2662493 | BC12: VMT (automobile, truck, motorcycle, buses) | BD12: 5 | BK12: 0.05*(TEmi_automobile+TEmi_truck+TEmi_buses+TEmi_motorcycle)
A13: T.l | B13: 40% passenger cars are replaced by electric vehicles | K13: X | L13: X | M13: X | N13: X | AZ13: =0.4*Summary!D2-1000000000*(0.4*Summary!H2)/(3000*2204.62*1000000) -> 0.41138977 | BA13: =AZ13*1000 -> 411.38977 | BB13: =AZ13/Summary!D$22*100 -> 6.4847691 | BC13: VMT (automobile) | BD13: 40 | BG13: VMT (automobile) | BH13: 40 in electricity generation emissions | BK13: 0.4*TEmi_automobile-1000000000*(0.4*VMT_automobile)/(3000*2204.62*1000000)
A14: T.m | B14: 10% reduction in the total vehicle emissions due to the adoption of renewable energy sources | O14: X | AZ14: =0.1*SUM(Summary!D2:D5) -> 0.28753893 | BA14: =AZ14*1000 -> 287.53893 | BB14: =AZ14/Summary!D$22*100 -> 4.5324986 | BC14: VMT (automobile, truck, motorcycle, buses) | BD14: 10 | BK14: 0.1*(TEmi_automobile+TEmi_truck+TEmi_buses+TEmi_motorcycle)
A15: E.a | B15: 10% reduction in the regional emissions factors | P15: X | Q15: X | R15: X | S15: X | U15: X | V15: X | W15: X | X15: X | AZ15: =0.1*SUM(Summary!D6:D7) -> 0.13149404 | BA15: =AZ15*1000 -> 131.49404 | BB15: =AZ15/Summary!D$22*100 -> 2.0727508 | BC15: Emissions factors (residential, industrial/ commercial) | BD15: 10 | BK15: 0.1*(EEmi_residential+EEmi_industrial/commercial)
A16: E.b | B16: 15% reduction in the regional emissions factors | P16: X | Q16: X | R16: X | S16: X | U16: X | V16: X | W16: X | X16: X | AZ16: =0.15*SUM(Summary!D6:D7) -> 0.19724106 | BA16: =AZ16*1000 -> 197.24106 | BB16: =AZ16/Summary!D$22*100 -> 3.1091262 | BC16: Emissions factors (residential, industrial/ commercial) | BD16: 15 | BK16: 0.15*(EEmi_residential+EEmi_industrial/commercial)
A17: E.c | B17: 20% reduction in the regional emissions factors | P17: X | Q17: X | R17: X | S17: X | U17: X | V17: X | W17: X | X17: X | AZ17: =0.2*SUM(Summary!D6:D7) -> 0.26298808 | BA17: =AZ17*1000 -> 262.98808 | BB17: =AZ17/Summary!D$22*100 -> 4.1455015 | BC17: Emissions factors (residential, industrial/ commercial) | BD17: 20 | BK17: 0.2*(EEmi_residential+EEmi_industrial/commercial)
A18: E.d | B18: 30% reduction in the regional emissions factors | P18: X | Q18: X | R18: X | S18: X | U18: X | V18: X | W18: X | X18: X | AZ18: =0.3*SUM(Summary!D6:D7) -> 0.39448212 | BA18: =AZ18*1000 -> 394.48212 | BB18: =AZ18/Summary!D$22*100 -> 6.2182523 | BC18: Emissions factors (residential, industrial/ commercial) | BD18: 30 | BK18: 0.3*(EEmi_residential+EEmi_industrial/commercial)
A19: E.e | B19: 40% reduction in wastewater emissions | T19: X | AZ19: =0.4*Summary!D18 -> 0.037142857 | BA19: =AZ19*1000 -> 37.142857 | BB19: =AZ19/Summary!D$22*100 -> 0.58548575 | BC19: Wastewater emissions | BD19: 40 | BK19: 0.4*Temi_wastewater
A20: E.f | B20: 10% reduction in the industrial electricity emissions | Y20: X | Z20: X | AZ20: =0.1*Summary!D7 -> 0.07028926 | BA20: =AZ20*1000 -> 70.28926 | BB20: =AZ20/Summary!D$22*100 -> 1.1079751 | BC20: Electricity consumption (industrial/ commercial) | BD20: 10 | BK20: 0.1*EEmi_industrial/commercial
A21: E.g | B21: 30% reduction in the industrial electricity emissions | Y21: X | Z21: X | AZ21: =0.3*Summary!D7 -> 0.21086778 | BA21: =AZ21*1000 -> 210.86778 | BB21: =AZ21/Summary!D$22*100 -> 3.3239252 | BC21: Electricity consumption (industrial/ commercial) | BD21: 30 | BK21: 0.3*EEmi_industrial/commercial
A22: B.a | B22: consumption of all fossil fuel in residential building reduces by 10% | AA22: X | AB22: X | AD22: X | AE22: X | AG22: X | AH22: X | AI22: X | AJ22: X | AK22: X | AL22: X | AM22: X | AZ22: =0.1*SUM(Summary!D10:D12) -> 0.136 | BA22: =AZ22*1000 -> 136 | BB22: =AZ22/Summary!D$22*100 -> 2.1437786 | BC22: Residential (fuel oil, natural gas, propane consumption) | BD22: 10 | BK22: 0.1*(TEmi_stationary_oil+TEmi_stationary_natural_gas+TEmi_stationary_propane)
A23: B.b | B23: consumption of all fossil fuel in residential building reduces by 20% | AA23: X | AB23: X | AD23: X | AE23: X | AG23: X | AH23: X | AI23: X | AJ23: X | AK23: X | AL23: X | AM23: X | AZ23: =0.2*SUM(Summary!D10:D12) -> 0.272 | BA23: =AZ23*1000 -> 272 | BB23: =AZ23/Summary!D$22*100 -> 4.2875572 | BC23: Residential (fuel oil, natural gas, propane consumption) | BD23: 20 | BK23: 0.2*(TEmi_stationary_oil+TEmi_stationary_natural_gas+TEmi_stationary_propane)
A24: B.c | B24: residential and commercial emissions reduced by 20% | AC24: X | AF24: X | AZ24: =0.2*SUM(Summary!D10:D12) -> 0.272 | BA24: =AZ24*1000 -> 272 | BB24: =AZ24/Summary!D$22*100 -> 4.2875572 | BC24: residential and commercial emissions | BD24: 20 | BK24: 0.2*(Temi_residential+Temi_commercial)
A25: B.d | B25: consumption of all fossil fuel in residential building reduces by 30% | AA25: X | AB25: X | AD25: X | AE25: X | AG25: X | AH25: X | AI25: X | AJ25: X | AK25: X | AL25: X | AM25: X | AZ25: =0.3*SUM(Summary!D10:D12) -> 0.408 | BA25: =AZ25*1000 -> 408 | BB25: =AZ25/Summary!D$22*100 -> 6.4313358 | BC25: Residential (fuel oil, natural gas, propane consumption) | BD25: 30 | BK25: 0.3*(TEmi_stationary_oil+TEmi_stationary_natural_gas+TEmi_stationary_propane)
A26: B.e | B26: consumption of all fossil fuel in residential building reduces by 40% | AA26: X | AB26: X | AD26: X | AE26: X | AG26: X | AH26: X | AI26: X | AJ26: X | AK26: X | AL26: X | AM26: X | AZ26: =0.4*SUM(Summary!D10:D12) -> 0.544 | BA26: =AZ26*1000 -> 544 | BB26: =AZ26/Summary!D$22*100 -> 8.5751144 | BC26: Residential (fuel oil, natural gas, propane consumption) | BD26: 40 | BK26: 0.4*(TEmi_stationary_oil+TEmi_stationary_natural_gas+TEmi_stationary_propane)
A27: B.f | B27: consumption of all fossil fuel in residential building reduces by 50% | AA27: X | AB27: X | AD27: X | AE27: X | AG27: X | AH27: X | AI27: X | AJ27: X | AK27: X | AL27: X | AM27: X | AZ27: =0.5*SUM(Summary!D10:D12) -> 0.68 | BA27: =AZ27*1000 -> 680 | BB27: =AZ27/Summary!D$22*100 -> 10.718893 | BC27: Residential (fuel oil, natural gas, propane consumption) | BD27: 50 | BK27: 0.5*(TEmi_stationary_oil+TEmi_stationary_natural_gas+TEmi_stationary_propane)
A28: B.g | B28: commerical buidling emissions reduce by 10% | AC28: X | AF28: X | AZ28: =0.1*Summary!D13 -> 0.096 | BA28: =AZ28*1000 -> 96 | BB28: =AZ28/Summary!D$22*100 -> 1.5132555 | BC28: commercial building emissions | BD28: 10 | BK28: 0.1*Temi_commercial_building
A29: B.h | B29: commerical buidling emissions reduce by 20% | AC29: X | AF29: X | AZ29: =0.2*Summary!D13 -> 0.192 | BA29: =AZ29*1000 -> 192 | BB29: =AZ29/Summary!D$22*100 -> 3.026511 | BC29: commercial building emissions | BD29: 20 | BK29: 0.2*Temi_commercial_building
A30: B.i | B30: commerical buidling emissions reduce by 30% | AC30: X | AF30: X | AZ30: =0.2*Summary!D13 -> 0.192 | BA30: =AZ30*1000 -> 192 | BB30: =AZ30/Summary!D$22*100 -> 3.026511 | BC30: commercial building emissions | BD30: 30 | BK30: 0.3*Temi_commercial_building
A31: B.j | B31: 50% reduction in the regional electricity emissions factors | AM31: X | AZ31: =0.5*SUM(Summary!D6:D7) -> 0.65747019 | BA31: =AZ31*1000 -> 657.47019 | BB31: =AZ31/Summary!D$22*100 -> 10.363754 | BC31: Emissions factors (residential, industrial/ commercial) | BD31: 50 | BK31: 0.5*(EEmi_residential+EEmi_industrial/commercial)
A32: I.a | B32: 10% reduction in healthcare emissions. | AN32: X | AO32: X | AP32: X | AZ32: =0.1*Summary!D14 -> 0.0339402 | BA32: =AZ32*1000 -> 33.9402 | BB32: =AZ32/Summary!D$22*100 -> 0.53500202 | BC32: Industrial (healthcare) | BD32: 10 | BK32: 0.1*TEmi_stationary_industrial
A33: I.b | B33: 20% reduction in healthcare emissions. | AN33: X | AO33: X | AP33: X | AZ33: =0.2*Summary!D14 -> 0.0678804 | BA33: =AZ33*1000 -> 67.8804 | BB33: =AZ33/Summary!D$22*100 -> 1.070004 | BC33: Industrial (healthcare) | BD33: 20 | BK33: 0.2*TEmi_stationary_industrial
A34: I.c | B34: 30% reduction in healthcare emissions. | AN34: X | AO34: X | AP34: X | AZ34: =0.3*Summary!D14 -> 0.1018206 | BA34: =AZ34*1000 -> 101.8206 | BB34: =AZ34/Summary!D$22*100 -> 1.605006 | BC34: Industrial (healthcare) | BD34: 30 | BK34: 0.3*TEmi_stationary_industrial
A35: L.a | B35: 20% increase in forest land area | AQ35: X | AR35: X | AS35: X | AZ35: =0.2*SUM(Summary!D19:D21) -> -0.12557825 | BA35: =AZ35*1000 -> -125.57825 | BB35: =AZ35/Summary!D$22*100 -> -1.9794997 | BC35: Forest land area | BD35: 20 | BK35: 0.2*(Seq_forest)
A36: L.b | B36: 10% increase in forest land area | AQ36: X | AR36: X | AS36: X | AZ36: =0.1*SUM(Summary!D19:D21) -> -0.062789123 | BA36: =AZ36*1000 -> -62.789123 | BB36: =AZ36/Summary!D$22*100 -> -0.98974984 | BC36: Forest land area | BD36: 10 | BK36: 0.1*(Seq_forest)
A37: L.c | B37: 20% reduction in agricultural emissions | AT37: X | AZ37: =0.2*SUM(Summary!D15:D17) -> 0.0058482172 | BA37: =AZ37*1000 -> 5.8482172 | BB37: =AZ37/Summary!D$22*100 -> 0.092185903 | BC37: agricultural emissions | BD37: 20 | BK37: 0.2*TEmi_agricultural
BK44: Labels:
BK45: TEmi: total greenhouse gas emissions
BK46: CEmi: carbon dioxide emissions
...

Sheet transposed
A1: Scenario | B1: T.1 | C1: T.2 | D1: T.3 | E1: T.4 | F1: T.5 | G1: T.6 | H1: T.7 | I1: T.8 | J1: T.9 | K1: T.10 | L1: T.11 | M1: T.12 | N1: T.13 | O1: E.1 | P1: E.2 | Q1: E.3 | R1: E.4 | S1: E.5 | T1: E.6 | U1: E.7 | V1: E.8 | W1: E.9 | X1: E.10 | Y1: E.11 | Z1: B.1 | AA1: B.2 | AB1: B.3 | AC1: B.4 | AD1: B.5 | AE1: B.6 | AF1: B.7 | AG1: B.8 | AH1: B.9 | AI1: B.10 | AJ1: B.11 | AK1: B.12 | AL1: B.13 | AM1: I.1 | AN1: I.2 | AO1: I.3 | AP1: L.1 | AQ1: L.2 | AR1: L.3 | AS1: L.4 | AT1: W.1 | AU1: W.2 | AV1: W.3 | AW1: W.4 | AX1: W.5 | AY1: Percentage of reduction %
A2: T.a | B2: 0.031895387 | AY2: 0.031895387
A3: T.b | C3: 1.4104901 | AY3: 1.4104901
A4: T.c | D4: 0.25336804 | AY4: 0.25336804
A5: T.d | E5: 0.77903561 | F5: 0.77903561 | G5: 0.77903561 | H5: 0.77903561 | I5: 0.77903561 | AY5: 0.77903561
A6: T.e | E6: 1.6059143 | F6: 1.6059143 | G6: 1.6059143 | H6: 1.6059143 | I6: 1.6059143 | AY6: 1.6059143
A7: T.f | E7: 0.7949833 | F7: 0.7949833 | G7: 0.7949833 | H7: 0.7949833 | I7: 0.7949833 | AY7: 0.7949833
A8: T.g | E8: 1.5899666 | F8: 1.5899666 | G8: 1.5899666 | H8: 1.5899666 | I8: 1.5899666 | AY8: 1.5899666
A9: T.h | E9: 1.5580712 | F9: 1.5580712 | G9: 1.5580712 | H9: 1.5580712 | I9: 1.5580712 | AY9: 1.5580712
A10: T.i | J10: 3.2423845 | K10: 3.2423845 | L10: 3.2423845 | M10: 3.2423845 | AY10: 3.2423845
A11: T.j | J11: 11.280232 | K11: 11.280232 | L11: 11.280232 | M11: 11.280232 | AY11: 11.280232
A12: T.k | L12: 2.2662493 | AY12: 2.2662493
A13: T.l | J13: 6.4847691 | K13: 6.4847691 | L13: 6.4847691 | M13: 6.4847691 | AY13: 6.4847691
A14: T.m | N14: 4.5324986 | AY14: 4.5324986
A15: E.a | O15: 2.0727508 | P15: 2.0727508 | Q15: 2.0727508 | R15: 2.0727508 | T15: 2.0727508 | U15: 2.0727508 | V15: 2.0727508 | W15: 2.0727508 | AY15: 2.0727508
A16: E.b | O16: 3.1091262 | P16: 3.1091262 | Q16: 3.1091262 | R16: 3.1091262 | T16: 3.1091262 | U16: 3.1091262 | V16: 3.1091262 | W16: 3.1091262 | AY16: 3.1091262
A17: E.c | O17: 4.1455015 | P17: 4.1455015 | Q17: 4.1455015 | R17: 4.1455015 | T17: 4.1455015 | U17: 4.1455015 | V17: 4.1455015 | W17: 4.1455015 | AY17: 4.1455015
A18: E.d | O18: 6.2182523 | P18: 6.2182523 | Q18: 6.2182523 | R18: 6.2182523 | T18: 6.2182523 | U18: 6.2182523 | V18: 6.2182523 | W18: 6.2182523 | AY18: 6.2182523
A19: E.e | S19: 0.58548575 | AY19: 0.58548575
A20: E.f | X20: 1.1079751 | Y20: 1.1079751 | AY20: 1.1079751
A21: E.g | X21: 3.3239252 | Y21: 3.3239252 | AY21: 3.3239252
A22: B.a | Z22: 2.1437786 | AA22: 2.1437786 | AC22: 2.1437786 | AD22: 2.1437786 | AF22: 2.1437786 | AG22: 2.1437786 | AH22: 2.1437786 | AI22: 2.1437786 | AJ22: 2.1437786 | AK22: 2.1437786 | AL22: 2.1437786 | AY22: 2.1437786
A23: B.b | Z23: 4.2875572 | AA23: 4.2875572 | AC23: 4.2875572 | AD23: 4.2875572 | AF23: 4.2875572 | AG23: 4.2875572 | AH23: 4.2875572 | AI23: 4.2875572 | AJ23: 4.2875572 | AK23: 4.2875572 | AL23: 4.2875572 | AY23: 4.2875572
A24: B.c | AB24: 4.2875572 | AE24: 4.2875572 | AY24: 4.2875572
A25: B.d | Z25: 6.4313358 | AA25: 6.4313358 | AC25: 6.4313358 | AD25: 6.4313358 | AF25: 6.4313358 | AG25: 6.4313358 | AH25: 6.4313358 | AI25: 6.4313358 | AJ25: 6.4313358 | AK25: 6.4313358 | AL25: 6.4313358 | AY25: 6.4313358
A26: B.e | Z26: 8.5751144 | AA26: 8.5751144 | AC26: 8.5751144 | AD26: 8.5751144 | AF26: 8.5751144 | AG26: 8.5751144 | AH26: 8.5751144 | AI26: 8.5751144 | AJ26: 8.5751144 | AK26: 8.5751144 | AL26: 8.5751144 | AY26: 8.5751144
A27: B.f | Z27: 10.718893 | AA27: 10.718893 | AC27: 10.718893 | AD27: 10.718893 | AF27: 10.718893 | AG27: 10.718893 | AH27: 10.718893 | AI27: 10.718893 | AJ27: 10.718893 | AK27: 10.718893 | AL27: 10.718893 | AY27: 10.718893
A28: B.g | AB28: 1.5132555 | AE28: 1.5132555 | AY28: 1.5132555
A29: B.h | AB29: 3.026511 | AE29: 3.026511 | AY29: 3.026511
A30: B.i | AB30: 3.026511 | AE30: 3.026511 | AY30: 3.026511
A31: B.j | AK31: 10.363754 | AY31: 10.363754
A32: I.a | AM32: 0.53500202 | AN32: 0.53500202 | AO32: 0.53500202 | AY32: 0.53500202
A33: I.b | AM33: 1.070004 | AN33: 1.070004 | AO33: 1.070004 | AY33: 1.070004
A34: I.c | AM34: 1.605006 | AN34: 1.605006 | AO34: 1.605006 | AY34: 1.605006
A35: L.a | AP35: -1.9794997 | AQ35: -1.9794997 | AR35: -1.9794997 | AY35: -1.9794997
A36: L.b | AP36: -0.98974984 | AQ36: -0.98974984 | AR36: -0.98974984 | AY36: -0.98974984
A37: L.c | AS37: 0.092185903 | AY37: 0.092185903

Sheet Policy Description
A1: Sector | B1: Goal | C1: Policy
A2: Mobility and transportation | B2: A Clean and Green Municipal Fleet | C2: T.1 Accelerate and/or begin adopting EV’s into the municipal fleet, including public school buses.
C3: T.2 Begin adopting alter_x0002_nate fuel sources such as hydrogen for medium to heavy-duty vehicles where EV transition is not possible.
C4: T.3 Reduce idling in mu_x0002_nicipal fleet; work with civil engineers to adjust traffic signals and pat_x0002_terns to reduce idle time.
B5: Create a transit first approach and reduce spatial misalignment | C5: T.4 Offer discounted transit fare for LIDACs
C6: T.5 Create a transit-first approach: a.Pilot pedestrianization, limited traffic (bus only lanes/streets) and use of active transportation downtown and dense developments. b. Ensure opportunity areas are completely accessible by transit. c. Advocate for transit plans that incentivize new development in areas that will allow for transit, walking, and bike use
C7: T.6 Reduce spatial misalign_x0002_ment through changes in land-use: Conduct feasibility stud_x0002_ies for creating economic zones in areas with high commute times. Encourage denser housing in areas near existing eco_x0002_nomic zones.
C8: T.7 Partner with micro-mobility companies to enable cross-town trips for smaller towns nearby.
C9: T.8 Create more park-and-ride options, and increase transit access and frequency in areas with high car owner_x0002_ship and high commute times to work to enable multi-modal trips.
B10: Reduce emissions from private vehicles | C10: T.9 Increase the overall Electric Vehicle adoption and create infrastructure to support this: • Communicate the benefits of CHEAPR to low and middle-income communities, and have limited time offers of higher Rebate+ to encourage buying of EVs in the short-term
C11: T.10 Incentivize EVs for shared-mobility companies (Uber/Lyft); this can even include free public parking for such vehicles
C12: T.11 Incentivize trip reduction programs in public offices and partner with private offices for the same: this basically requires an increase in work-from-home so that work-commute is reduced.
C13: T.12 Improve broadband access (with at least 1GBPS) state-wide
C14: T.13 Pursue alternative fuel sources, such as hydrogen, where electrification is not possible
A15: Electricity Production and Consumption | B15: Reduce electricity consumption from fossil fuel sources in municipal buildings and services | C15: E.1 Utilize on site renew_x0002_ables (ie. rooftop solar) to power municipal operations
C16: E.2 leverage powers of municipal utilities to pro_x0002_cure renewable power, ex_x0002_pand electricity production capabilities, and/or invest in storage capabilities with_x0002_in the municipality
C17: E.3 Increase procurement of renewable energy for municipal services
C18: E.4 Pursue microgrid projects that integrate onsite renewables and electricity from the grid to power municipal services
C19: E.5 Increase efficiency of wastewater treatment facilities, utilize onsite solar, or biogas to lower emissions at these facilities
B20: Increase renewable energy production and consumption at the local scale | C20: E.6 Set up outreach programs that communicate state and federal level financing programs that support on site renewable generation to consumers.
C21: E.7 Evaluate the potential of citing renewable energy projects on vacant, underutilized land/combine with open space planning
C22: E.8 Consider adopting clean energy zoning ordinances that would require new and/or existing buildings to meet certain clean energy milestones through the use of onsite renewables or clean energy purchasing
C23: E.9 Coordinate through housing authorities to build out community solar projects and microgrids for public housing complexe
B24: Prepare local economies for renewable energy transition | C24: E.10 Prepare economic development plans around offshore wind energy
C25: E.11 Partner with local workforce development centers and union chapters to prepare workforce in key renewable energy sectors, such as offshore wind en_x0002_ergy and solar installations
A26: Energy Efficiency in Buildings | B26: Building Energy Benchmarking and Disclosure for existing and new buildings | C26: B.1 - Require building own_x0002_ers to annually benchmark and disclose their energy usage and efficiency rat_x0002_ings
C27: B.2 - Provide educational resources and support to building owners to help them understand and im_x0002_prove energy performance
C28: B.3 - Ensure all municipal operations rely on 100% renewable energy source
C29: B.4 - Advocate for strict building codes and achieve net zero energy usage
C30: B.5 - Offer incentives and expedited permit_x0002_ting for projects that achieve green building certifications
C31: B.6.-Support climate friendly land use: develop robust resources to enable municipalities to implement model climate-friendly land use and zoning practices.
B32: Renewable Energy Access for low Income Homes | C32: B.7 - Install solar heating on low income housing units o generate clean, renewable energy and reduce electric_x0002_ity costs
C33: B.8- Develop community solar heating programs that allow low-income residents to benefit from shared solar installations
C34: B.9 - Install energy monitoring and management systems in low-income housing to track and control energy consumption.
B35: Energy-efficient Building Materials and Retrofits | C35: B.10- Support the adoption of sustainable building materials in low income housing construction and renovation
C36: B.11 - Establish a city-wide retrofit program especially for low income and municipal buildings, providing grants and low-interest loans to property owners for energy-efficient upgrades
C37: B.12 - Monitor and report the energy and cost savings resulting from retrofitting and sustainable materials to demonstrate their impact and encourage further investment.
C38: B.13-Set up outreach programs at the regional or local level that target LMI households for heat pump installations and energy efficiency upgrades. - Highlight the benefits of HEATsmart programs to increase heat pump uptake in LIDAC communities. - Partner with social service and community-based agencies for assistance on outreach into LIDAC areas. - Highlight the benefits of other state and federal incentives for heat pump installation and energy efficiency upgrades, such as HES-IE through EnergizeCT.
A39: Industrial | B39: Improve Emissions Monitoring, Accounting and Reporting | C39: I.1 - Require utility companies, gas sup_x0002_pliers, and health care establishments to report emissions data
B40: Reduce emissions through low-carbon procurement | C40: I.2 Embed a purchasing criterion in public projects that states a preference for suppli_x0002_ers or service providers who have a trans_x0002_parent and standardized GHG inventory.
...
